test('Não deveria passar!', () => {
  setTimeout(() => {
    expect(10).toBe(5);
    console.log('Deveria falhar!');
  }, 500);
});
// retorna um resultado falso-positivo quando executado dessa forma — note, inclusive, que a frase "Deveria falhar!" sequer aparece no console.



test('Não deveria passar!', (done) => {
  setTimeout(() => {
    expect(10).toBe(5);
    console.log('Deveria falhar!');
    done();
  }, 500);
});
// Apesar do código acima parecer correto, irá falhar com uma mensagem de timeout. O motivo é que quando uma asserção (verificação) falha, a exceção é lançada, ou seja, algo inesperado aconteceu



test('Não deveria passar!', (done) => {
  setTimeout(() => {
    try {
      expect(10).toBe(5);
      console.log('Deveria falhar!');
      done();
    } catch (error) {
      done();
    }
  }, 500);
});
// Estamos quase lá... O código acima irá gerar um falso-positivo. O motivo é que não estamos passando nenhuma ação a ser realizada quando o erro acontece e "encerramos" nosso teste com o done() sem lançar nenhum erro, dessa forma o teste é interpretado como "correto"



test('Não deveria passar!', (done) => {
  setTimeout(() => {
    try {
      expect(10).toBe(5);
      console.log('Deveria falhar!');
      done();
    } catch (error) {
      done(error); // Alteramos esta linha
    }
  }, 500);
});
// Agora o test falhou como esperado




// Outro exemplo
const asyncSum = (a, b, callback) => {
  setTimeout(() => {
    const result = a + b;
    callback(result);
  }, 500);
};

test('Testando asyncSum, soma 5 mais 10', (done) => {
  asyncSum(5, 10, (result) => {
    try {
      expect(result).toBe(15);
      done();
    } catch (error) {
      done(error);
    }
  });
});
